Workbook

Sheet TCO_3yr
A1: 3-Year Total Cost of Ownership – Snowflake vs Google BigQuery
A2: Same workload for both platforms. All values are formulas from the Assumptions sheet.
A4: Line item | B4: Year 1 | C4: Year 2 | D4: Year 3 | E4: 3-year total | G4: Chart data (3-yr)
A5: Workload | G5: Category | H5: Snowflake | I5: BigQuery
A6: Data volume (GB, compressed) | B6: =Assumptions!$B$7 -> 50 | C6: =B6*(1+Assumptions!$B$8) -> 75 | D6: =C6*(1+Assumptions!$B$8) -> 112.5 | G6: Platform | H6: =E15 -> 4501.0781 | I6: =E29 -> 1946.9924
A7: Snowflake compute scale (×) | B7: =1 -> 1 | C7: =B7*(1+Assumptions!$B$8*Assumptions!$B$19) -> 1.25 | D7: =C7*(1+Assumptions!$B$8*Assumptions!$B$19) -> 1.5625 | G7: Migration + setup | H7: =E18 -> 5280 | I7: =E32 -> 5520
G8: Training | H8: =E19 -> 1440 | I8: =E33 -> 1800
A9: Snowflake – platform | G9: Admin | H9: =E20 -> 8640 | I9: =E34 -> 8640
A10: Warehouse hours / month | B10: =((Assumptions!$B$9*(Assumptions!$B$15+Assumptions!$B$16))+(Assumptions!$B$10*Assumptions!$B$17)+(Assumptions!$B$11*Assumptions!$B$18))/60*B7 -> 27 | C10: =((Assumptions!$B$9*(Assumptions!$B$15+Assumptions!$B$16))+(Assumptions!$B$10*Assumptions!$B$17)+(Assumptions!$B$11*Assumptions!$B$18))/60*C7 -> 33.75 | D10: =((Assumptions!$B$9*(Assumptions!$B$15+Assumptions!$B$16))+(Assumptions!$B$10*Assumptions!$B$17)+(Assumptions!$B$11*Assumptions!$B$18))/60*D7 -> 42.1875
A11: Credits / year | B11: =B10*Assumptions!$B$14*12 -> 324 | C11: =C10*Assumptions!$B$14*12 -> 405 | D11: =D10*Assumptions!$B$14*12 -> 506.25 | E11: =SUM(B11:D11) -> 1235.25
A12: Compute ($) | B12: =B11*Assumptions!$B$13 -> 972 | C12: =C11*Assumptions!$B$13 -> 1215 | D12: =D11*Assumptions!$B$13 -> 1518.75 | E12: =SUM(B12:D12) -> 3705.75
A13: Storage ($) | B13: =B6/1024*Assumptions!$B$20*12 -> 23.4375 | C13: =C6/1024*Assumptions!$B$20*12 -> 35.15625 | D13: =D6/1024*Assumptions!$B$20*12 -> 52.734375 | E13: =SUM(B13:D13) -> 111.32812
A14: Google Ads connector ($) | B14: =Assumptions!$B$21*12 -> 228 | C14: =Assumptions!$B$21*12 -> 228 | D14: =Assumptions!$B$21*12 -> 228 | E14: =SUM(B14:D14) -> 684
A15: Snowflake platform subtotal | B15: =SUM(B12:B14) -> 1223.4375 | C15: =SUM(C12:C14) -> 1478.1562 | D15: =SUM(D12:D14) -> 1799.4844 | E15: =SUM(B15:D15) -> 4501.0781
A17: Snowflake – hidden costs (labor)
A18: Migration + setup ($) | B18: =(Assumptions!$B$37+Assumptions!$B$22)*Assumptions!$B$5 -> 5280 | C18: =0 -> 0 | D18: =0 -> 0 | E18: =SUM(B18:D18) -> 5280
A19: Training ($) | B19: =Assumptions!$B$6*Assumptions!$B$23*Assumptions!$B$5 -> 1440 | C19: =0 -> 0 | D19: =0 -> 0 | E19: =SUM(B19:D19) -> 1440
A20: Admin ($) | B20: =Assumptions!$B$24*12*Assumptions!$B$5 -> 2880 | C20: =Assumptions!$B$24*12*Assumptions!$B$5 -> 2880 | D20: =Assumptions!$B$24*12*Assumptions!$B$5 -> 2880 | E20: =SUM(B20:D20) -> 8640
A21: SNOWFLAKE TOTAL | B21: =B15+SUM(B18:B20) -> 10823.438 | C21: =C15+SUM(C18:C20) -> 4358.1562 | D21: =D15+SUM(D18:D20) -> 4679.4844 | E21: =SUM(B21:D21) -> 19861.078
A23: Google BigQuery – platform
A24: Data scanned / month (TiB) | B24: =(Assumptions!$B$9*Assumptions!$B$28+Assumptions!$B$10*Assumptions!$B$29)*B6/1024 -> 5.9570312 | C24: =(Assumptions!$B$9*Assumptions!$B$28+Assumptions!$B$10*Assumptions!$B$29)*C6/1024 -> 8.9355469 | D24: =(Assumptions!$B$9*Assumptions!$B$28+Assumptions!$B$10*Assumptions!$B$29)*D6/1024 -> 13.40332
A25: Billable TiB / month (after free tier) | B25: =MAX(0,B24-Assumptions!$B$27) -> 4.9570312 | C25: =MAX(0,C24-Assumptions!$B$27) -> 7.9355469 | D25: =MAX(0,D24-Assumptions!$B$27) -> 12.40332
A26: Compute ($) | B26: =B25*Assumptions!$B$26*12 -> 371.77734 | C26: =C25*Assumptions!$B$26*12 -> 595.16602 | D26: =D25*Assumptions!$B$26*12 -> 930.24902 | E26: =SUM(B26:D26) -> 1897.1924
A27: Storage ($) | B27: =MAX(0,B6-Assumptions!$B$31)*Assumptions!$B$30*12 -> 9.6 | C27: =MAX(0,C6-Assumptions!$B$31)*Assumptions!$B$30*12 -> 15.6 | D27: =MAX(0,D6-Assumptions!$B$31)*Assumptions!$B$30*12 -> 24.6 | E27: =SUM(B27:D27) -> 49.8
A28: Google Ads connector ($) | B28: =Assumptions!$B$32*12 -> 0 | C28: =Assumptions!$B$32*12 -> 0 | D28: =Assumptions!$B$32*12 -> 0 | E28: =SUM(B28:D28) -> 0
A29: BigQuery platform subtotal | B29: =SUM(B26:B28) -> 381.37734 | C29: =SUM(C26:C28) -> 610.76602 | D29: =SUM(D26:D28) -> 954.84902 | E29: =SUM(B29:D29) -> 1946.9924
A31: Google BigQuery – hidden costs (labor)
A32: Migration + setup ($) | B32: =(Assumptions!$B$37+Assumptions!$B$33)*Assumptions!$B$5 -> 5520 | C32: =0 -> 0 | D32: =0 -> 0 | E32: =SUM(B32:D32) -> 5520
A33: Training ($) | B33: =Assumptions!$B$6*Assumptions!$B$34*Assumptions!$B$5 -> 1800 | C33: =0 -> 0 | D33: =0 -> 0 | E33: =SUM(B33:D33) -> 1800
A34: Admin ($) | B34: =Assumptions!$B$35*12*Assumptions!$B$5 -> 2880 | C34: =Assumptions!$B$35*12*Assumptions!$B$5 -> 2880 | D34: =Assumptions!$B$35*12*Assumptions!$B$5 -> 2880 | E34: =SUM(B34:D34) -> 8640
A35: BIGQUERY TOTAL | B35: =B29+SUM(B32:B34) -> 10581.377 | C35: =C29+SUM(C32:C34) -> 3490.766 | D35: =D29+SUM(D32:D34) -> 3834.849 | E35: =SUM(B35:D35) -> 17906.992
A37: Comparison
A38: Difference (Snowflake − BigQuery) ($) | B38: =B21-B35 -> 242.06016 | C38: =C21-C35 -> 867.39023 | D38: =D21-D35 -> 844.63535 | E38: =SUM(B38:D38) -> 1954.0857
A39: Difference as % of BigQuery 3-yr TCO | E39: =IF(E35=0,0,E38/E35) -> 0.10912417
A40: Decision rule (Step 2): TCO gap under 20%? | E40: =IF(ABS(E39)<0.2,"YES – cost does not decide; non-cost criteria decide","NO – cost decides") -> YES – cost does not decide; non-cost criteria decide
A41: Within $150K Phase 1 budget? | E41: =IF(MAX(E21,E35)<=Assumptions!$B$38,"Both within budget","Check budget") -> Both within budget
A42: Labor share of Snowflake 3-yr TCO | E42: =IF(E21=0,0,SUM(E18:E20)/E21) -> 0.77337191
A43: Labor share of BigQuery 3-yr TCO | E43: =IF(E35=0,0,SUM(E32:E34)/E35) -> 0.89127195

Sheet Assumptions
A1: Assumptions – Build-A-Bear Phase 1 (marketing & e-commerce analytics)
A2: Blue = input you can change · Yellow = key assumption · All other sheets are formulas
A3: Input | B3: Value | C3: Unit | D3: Source / rationale
A4: Shared workload
A5: Analyst loaded hourly cost | B5: 60 | C5: $/hour | D5: Assumption: ~$95K salary + 30% benefits ÷ 2,080 h. Verify vs BLS OOH (data analyst/scientist).
A6: Analysts using the platform | B6: 3 | C6: people | D6: Business scenario (Step 2)
A7: Data volume, year 1 (compressed) | B7: 50 | C7: GB | D7: Assumption: PoC = 19 MB for one small store; scaled for 2 e-commerce sites + ad data
A8: Annual data growth | B8: 0.5 | C8: %/yr | D8: PoC data: sessions 62k → 113k → 233k per year (≈ +50–100%)
A9: Dashboard refreshes per month | B9: 360 | C9: runs | D9: Hourly, 12 h/day × 30 days (Step 2)
A10: Ad-hoc queries per month | B10: 200 | C10: queries | D10: Business scenario (Step 2)
A11: Data loads (ETL) per month | B11: 30 | C11: loads | D11: One daily load
A12: Snowflake
A13: Price per credit (Enterprise, AWS US East) | B13: 3 | C13: $/credit | D13: Published pricing guides (Redress, Espresso AI) – verify snowflake.com/pricing
A14: Credits per hour – X-Small warehouse | B14: 1 | C14: credits/h | D14: Snowflake warehouse sizing; PoC used X-Small
A15: Dashboard query runtime per refresh | B15: 1 | C15: min | D15: PoC: channel query 1.33 s on 19 MB; allow ~1 min at production size
A16: Auto-suspend after idle | B16: 1 | C16: min | D16: PoC setting FUZZY_WH AUTO_SUSPEND = 60 s
A17: Billable minutes per ad-hoc query | B17: 3 | C17: min | D17: Assumption incl. idle time before suspend
A18: Minutes per daily data load | B18: 10 | C18: min | D18: Assumption
A19: Compute-hours growth as share of data growth | B19: 0.5 | C19: × | D19: Assumption: pruning + result cache → runtime grows slower than data
A20: Storage price | B20: 40 | C20: $/TB/month | D20: On-demand rate in pricing guides (≈$23 with capacity contract)
A21: Google Ads connector | B21: 19 | C21: $/month | D21: Third-party connector, e.g. Windsor.ai starter tier
A22: Platform setup (production) | B22: 8 | C22: hours | D22: PoC setup took ~2.5 h incl. troubleshooting (26-Oct); ×3 for production
A23: Training per analyst | B23: 8 | C23: hours | D23: Free Snowflake Quickstarts; SQL skills transfer directly
A24: Admin per month | B24: 4 | C24: hours | D24: Users/roles, resource monitors, warehouse settings
A25: Google BigQuery
A26: On-demand query price | B26: 6.25 | C26: $/TiB scanned | D26: cloud.google.com/bigquery/pricing (official)
A27: Free query allowance | B27: 1 | C27: TiB/month | D27: cloud.google.com/bigquery/pricing (official)
A28: Data scanned per dashboard refresh | B28: 0.2 | C28: % of data | D28: Assumption: partitioned + clustered tables, few columns
A29: Data scanned per ad-hoc query | B29: 0.25 | C29: % of data | D29: Assumption
A30: Storage price (active) | B30: 0.02 | C30: $/GB/month | D30: Pricing guides (Revefi, Airbyte) – verify Google page
A31: Free storage | B31: 10 | C31: GB/month | D31: Pricing guide (Portable) – verify
A32: Google Ads connector (Data Transfer Service) | B32: 0 | C32: $/month | D32: Reported free; storage/query billed (verify DTS pricing)
A33: Platform setup (production) | B33: 12 | C33: hours | D33: Assumption: GCP project, billing, IAM, Data Transfer config
A34: Training per analyst | B34: 10 | C34: hours | D34: Assumption: SQL + GCP IAM + scan-cost discipline (partitioning)
A35: Admin per month | B35: 4 | C35: hours | D35: IAM, quotas / max-bytes-billed, cost monitoring
A36: Both platforms
A37: Report & data migration effort | B37: 80 | C37: hours | D37: Assumption: rebuild 6 tables + channel ROI reports + testing
A38: Phase 1 budget (3 years) | B38: 150000 | C38: $ | D38: Business scenario (Step 2)
A39: Value (same for both platforms)
A40: Reporting hours saved per analyst per week | B40: 8 | C40: hours | D40: Success criterion: −80% reporting time ≈ 1 day/week
...

Sheet Sensitivity
A1: Sensitivity – what happens when cost controls are ignored? (Year 1 platform cost)
A2: Each platform has one cost risk that customers complain about in reviews. Year 1 data volume.
A4: Scenario | B4: Setting | C4: Snowflake Y1 platform ($) | D4: BigQuery Y1 platform ($) | E4: Careless input | F4: Value
A5: Base (disciplined) | B5: Auto-suspend 1 min · partitioned tables | C5: =TCO_3yr!B15 -> 1223.4375 | D5: =TCO_3yr!B29 -> 381.37734 | E5: Snowflake auto-suspend (min) | F5: 10
A6: Careless | B6: Auto-suspend 10 min · SELECT * full scans | C6: =((Assumptions!$B$9*(Assumptions!$B$15+F5))+(Assumptions!$B$10*Assumptions!$B$17)+(Assumptions!$B$11*Assumptions!$B$18))/60*Assumptions!$B$14*12*Assumptions!$B$13+TCO_3yr!B13+TCO_3yr!B14 -> 3167.4375 | D6: =MAX(0,(Assumptions!$B$9+Assumptions!$B$10)*F6*TCO_3yr!B6/1024-Assumptions!$B$27)*Assumptions!$B$26*12+TCO_3yr!B27+TCO_3yr!B28 -> 1985.3812 | E6: BigQuery scan share per query | F6: 1
A7: Cost multiplier (careless ÷ base) | C7: =IF(C5=0,0,C6/C5) -> 2.5889655 | D7: =IF(D5=0,0,D6/D5) -> 5.2058185
A9: Control that prevents it | C9: Auto-suspend + resource monitors (credit quota) | D9: Max-bytes-billed + custom quotas + partitioning
A10: Lesson from my PoC | C10: 91% of PoC credits came from the default COMPUTE_WH, not the 60-s auto-suspend FUZZY_WH

Sheet Value_ROI
A1: Business value over 3 years (same for both platforms)
A3: Item | B3: Value ($)
A4: FTE reallocation per year (analyst hours saved) | B4: =Assumptions!$B$6*Assumptions!$B$40*Assumptions!$B$41*Assumptions!$B$5 -> 69120
A5: Revenue capture per year (better channel allocation) | B5: =Assumptions!$B$42*Assumptions!$B$43 -> 97191.2
A6: Total value per year | B6: =B4+B5 -> 166311.2
A7: Total value over 3 years | B7: =B6*3 -> 498933.6
A9: 3-year ROI – Snowflake | B9: =IF(TCO_3yr!E21=0,0,(B7-TCO_3yr!E21)/TCO_3yr!E21) -> 24.121174
A10: 3-year ROI – BigQuery | B10: =IF(TCO_3yr!E35=0,0,(B7-TCO_3yr!E35)/TCO_3yr!E35) -> 26.862501
A11: Payback – Snowflake (months) | B11: =IF(B6=0,0,TCO_3yr!E21/B6*12) -> 1.433054
A12: Payback – BigQuery (months) | B12: =IF(B6=0,0,TCO_3yr!E35/B6*12) -> 1.2920592
A14: Reading: the analytics project pays back fast on either platform – so the platform choice rests on TCO and the scoring matrix.

Sheet Scoring
A1: Weighted scoring matrix (1 = poor … 5 = excellent)
A3: Criterion | B3: Weight | C3: Why this weight | D3: Snowflake | E3: BigQuery | F3: Evidence
A4: Pricing / 3-yr TCO | B4: 0.3 | C4: Retailer under margin pressure (guidance cut Aug-2026) | D4: 4 | E4: 5 | F4: BigQuery 3-yr TCO lower (free tier, free Ads connector) – see TCO_3yr; gap under 20%
A5: Scalability | B5: 0.25 | C5: Traffic doubling + holiday peaks | D5: 5 | E5: 5 | F5: Both fully managed & elastic: Snowflake resizes/multi-cluster; BigQuery serverless
A6: Usability | B6: 0.2 | C6: Small analytics team, no platform engineers | D6: 5 | E6: 4 | F6: PoC: data + users + MFA in ~2.5 h; roles simple. Gartner 4.7 vs 4.5; BigQuery needs GCP IAM
A7: Business fit | B7: 0.25 | C7: Google Ads data + partners + U.S./Europe | D7: 4 | E7: 4 | F7: BQ: native Google Ads/GA4. SF: multi-cloud, no lock-in, secure sharing with agencies/licensing partners
A8: Weighted total | B8: =SUM(B4:B7) -> 1 | D8: =SUMPRODUCT($B$4:$B$7,D4:D7) -> 4.45 | E8: =SUMPRODUCT($B$4:$B$7,E4:E7) -> 4.55
A9: Non-cost criteria only (rule applies when TCO gap < 20%) | D9: =SUMPRODUCT($B$5:$B$7,D5:D7) -> 3.25 | E9: =SUMPRODUCT($B$5:$B$7,E5:E7) -> 3.05
A10: Decision | D10: =IF(TCO_3yr!E40="NO – cost decides",IF(D8>=E8,"Snowflake","BigQuery"),IF(D9>=E9,"Snowflake","BigQuery")) -> Snowflake

Sheet PoC_Measured
A1: Measured in my Snowflake trial (26-Oct-2026, account JDKUHSR-QK22783)
A3: Item | B3: Value | C3: Source
A4: Rows loaded (6 tables) | B4: 1735068 | C4: Row-count check after COPY INTO
A5: Raw CSV size (MB) | B5: 102.9 | C5: File sizes on disk
A6: Stored size in Snowflake (MB) | B6: 19 | C6: INFORMATION_SCHEMA.TABLES bytes
A7: Credits – FUZZY_WH | B7: 0.0516 | C7: WAREHOUSE_METERING_HISTORY
A8: Credits – COMPUTE_WH (default) | B8: 0.5316 | C8: WAREHOUSE_METERING_HISTORY
A9: Credits – cloud services | B9: 0.0006 | C9: WAREHOUSE_METERING_HISTORY
A10: Submission query runtime (s), EXT_TEST_USER | B10: 1.33 | C10: ACCOUNT_USAGE.QUERY_HISTORY
A11: Submission query data scanned (MB) | B11: 3.3 | C11: ACCOUNT_USAGE.QUERY_HISTORY
A12: Setup time incl. troubleshooting (h, approx.) | B12: 2.5 | C12: Screenshot timestamps 10:39–13:00 – confirm
A13: Total credits | B13: =SUM(B7:B9) -> 0.5838
A14: PoC compute cost ($) | B14: =B13*Assumptions!$B$13 -> 1.7514
A15: Compression ratio | B15: =IF(B6=0,0,B5/B6) -> 5.4157895
A16: Share of credits from default COMPUTE_WH | B16: =IF(B13=0,0,B8/B13) -> 0.91058582
